<?xml version='1.0'?>
<robot name="dd_robot">
    <link name="base_link">
        <visual>
            <origin xyz="0.0 0.0 0.0"  rpy="0.0 0.0 0.0"/>
            <geometry>
                <box size="0.5 0.5 0.25" />
            </geometry>
            <material name="blue">
                <color rgba="0.0 0.5 1.0 1.0"/>
            </material>
        </visual>
	    <collision>
            <origin xyz="0.0 0.0 0.0" rpy="0.0 0.0 0.0"/>
            <geometry>
                <box size="0.5 0.5 0.25"/>
            </geometry>
        </collision>
        <inertial>
            <mass value="5"/>
            <inertia ixx="0.13" ixy="0.0" ixz="0.0" iyy="0.21" iyz="0.0" izz="0.13"/>
        </inertial>
	    <visual name="caster">
            <origin xyz="0.2 0.0 -0.125" rpy="0.0 0.0 0.0"/>
            <geometry>
                <sphere radius="0.05"/>
            </geometry>
        </visual>
	    <collision>
            <origin xyz="0.2 0.0 -0.125" rpy="0.0 0.0 0.0"/>
            <geometry>
                <sphere radius="0.05"/>
            </geometry>
        </collision>
    </link>


    <link name="right_wheel">
        <visual>
            <origin xyz="0.0 -0.0 0.0" rpy="1.570795 0.0 0.0"/>
            <geometry>
                <cylinder length="0.1" radius="0.2"/>
            </geometry>
	    <material name="black">
                <color rgba="0.05 0.05 0.05 1.0"/>
            </material>
        </visual>
	    <collision>
            <origin xyz="0.0 0.0 0.0" rpy="1.570795 0.0 0.0"/>
            <geometry>
                <cylinder length="0.1" radius="0.2"/>
            </geometry>
        </collision>
    </link>


    <joint name="join_right_wheel" type="continuous">
        <parent link="base_link"/>
        <child link="right_wheel"/>
        <origin xyz="0.0 -0.30 0.0" rpy="0.0 0.0 0.0"/>
        <axis xyz="0.0 1.0 0.0"/>
    </joint>


    <link name="left_wheel">
        <visual>
            <origin xyz="0.0 0.0 0.0" rpy="1.570795 0.0 0.0"/>
            <geometry>
                <cylinder length="0.1" radius="0.2"/>
            </geometry>

	    <material name="black"/>
        </visual>
	    <collision>
            <origin xyz="0.0 0.0 0.0" rpy="1.570795 0.0 0.0"/>
            <geometry>
                <cylinder length="0.1" radius="0.2"/>
            </geometry>
        </collision>
    </link>


    <joint name="join_left_wheel" type="continuous">
        <parent link="base_link"/>
        <child link="left_wheel"/>
        <origin xyz="0.0 -0.3 0.0" rpy="0.0 0.0 0.0"/>
        <axis xyz="0.0 1.0 0.0"/>
    </joint>


　　<gazebo reference="base_link">
	    <material>Gazebo/Blue</material>
    </gazebo>
　　<gazebo reference="right_wheel">
	    <material>Gazebo/Black</material>
    </gazebo>
    <gazebo reference="left_wheel">
	    <material>Gazebo/Black</material>
    </gazebo>
</robot>

